Workbook
Name SKU_List: 'Item Master'!$A$4:$A$53
Name TXN_List: 'Log Transaction'!$B$4:$B$303

Sheet Start Here
A1: =HYPERLINK("#'Dashboard'!A1","🏠 Dashboard") | C1: =HYPERLINK("#'Item Master'!A1","📦 Products") | D1: =HYPERLINK("#'Log Transaction'!A1","✍️ Log Sale") | E1: =HYPERLINK("#'Invoice Generator'!A1","🧾 Invoice") | F1: =HYPERLINK("#'Start Here'!A1","🚀 Start Here")
B4: MOMENTUM MIND STORE
B5: 📦 Inventory Manager PRO
B6: Track stock, log every sale, and send invoices — from your phone.
B8: 📦 STEP 1 — Add your products
B9: Open the Products screen and fill one row per item. SKU must be unique — it is the key that powers everything else.
B11: ⚙️ STEP 2 — Set your business details
B12: Open Settings and enter your shop name, contact details, tax rate and invoice prefix. Every invoice reads from there.
B14: ✍️ STEP 3 — Log every movement
B15: On the Log Sale screen, tap a new row. Pick the SKU from the dropdown, choose IN (stock received), OUT (sold) or SHRINKAGE (damaged/lost), and enter the quantity. The Total fills itself.
B17: 🧾 STEP 4 — Generate an invoice
B18: Type or pick a Transaction ID at the top of the Invoice screen. Every line for that ID appears instantly. Share ▸ Export as PDF.
B20: 🏠 STEP 5 — Watch the Dashboard
... B23: 🎨 COLOUR KEY
B24: 🟡 Yellow cells | C24: You type here.
B25: ⬜ White cells | C25: Calculated automatically — do not overwrite.
B26: 🟦 Dark bar (top) | C26: Tap any label to jump between screens.
B28: 💬 NEED HELP?
B29: ✉️ Support email | C29: =HYPERLINK("mailto:support@momentummindstore.com?subject=Inventory%20Manager%20PRO%20-%20Support","support@momentummindstore.com")
B30: 🛍️ Etsy shop | C30: =HYPERLINK("https://www.etsy.com/shop/MomentumMindStore","etsy.com/shop/MomentumMindStore")
B31: 📖 Video walkthrough | C31: =HYPERLINK("https://www.momentummindstore.com/inventory-pro-guide","Watch the 4-minute setup video")
B32: ⭐ Loved it? | C32: =HYPERLINK("https://www.etsy.com/your/purchases","Leave a review — it genuinely helps a small shop")
B34: © Momentum Mind Store — single-shop licence. No resale or redistribution of this file.

Sheet Dashboard
A1: =HYPERLINK("#'Dashboard'!A1","🏠 Dashboard") | C1: =HYPERLINK("#'Item Master'!A1","📦 Products") | E1: =HYPERLINK("#'Log Transaction'!A1","✍️ Log Sale") | F1: =HYPERLINK("#'Invoice Generator'!A1","🧾 Invoice") | G1: =HYPERLINK("#'Start Here'!A1","🚀 Start Here")
A4: LIVE OVERVIEW
A5: 🏠 Dashboard
A6: Stock recalculates the moment you log a transaction.
A7: =COUNTA('Item Master'!$A$4:$A$53) | C7: =SUM($E$9:$E$58) | E7: =SUM($I$9:$I$58) | G7: =COUNTIF($F$9:$F$58,"⚠️ REORDER NOW")
A8: SKU | B8: 📦 Product | C8: ⬇ Total IN | D8: ⬆ Total OUT | E8: 📊 Current Stock | F8: 🚦 Stock Status | G8: 💬 WhatsApp Order | H8: ✉️ Email Order | I8: Value
A9: =IF(INDEX('Item Master'!$A$4:$A$53,1)="","",INDEX('Item Master'!$A$4:$A$53,1)) | B9: =IF($A9="","",_xlfn.XLOOKUP($A9,'Item Master'!$A$4:$A$53,'Item Master'!$B$4:$B$53,"")) | C9: =IF($A9="","",SUMIFS('Log Transaction'!$E$4:$E$303,'Log Transaction'!$C$4:$C$303,$A9,'Log Transaction'!$D$4:$D$303,"IN")) | D9: =IF($A9="","",SUMIFS('Log Transaction'!$E$4:$E$303,'Log Transaction'!$C$4:$C$303,$A9,'Log Transaction'!$D$4:$D$303,"OUT")+SUMIFS('Log Transaction'!$E$4:$E$303,'Log Transaction'!$C$4:$C$303,$A9,'Log Transaction'!$D$4:$D$303,"SHRINKAGE")) | E9: =IF($A9="","",$C9-$D9) | F9: =IF($A9="","",IF($E9<=_xlfn.XLOOKUP($A9,'Item Master'!$A$4:$A$53,'Item Master'!$F$4:$F$53,0)*0.1,"⚠️ REORDER NOW","✅ IN STOCK")) | G9: =IF($A9="","",IF($F9="⚠️ REORDER NOW",HYPERLINK("https://wa.me/"&SUBSTITUTE(SUBSTITUTE(SUBSTITUTE(SUBSTITUTE(SUBSTITUTE(SUBSTITUTE(_xlfn.XLOOKUP($A9,'Item Master'!$A$4:$A$53,'Item Master'!$I$4:$I$53,""),"+",""),"-","")," ",""),"(",""),")",""),".","")&"?text="&SUBSTITUTE("Hello "&_xlfn.XLOOKUP($A9,'Item Master'!$A$4:$A$53,'Item Master'!$H$4:$H$53,"Supplier")&", we urgently need more "&$B9&". Current stock is only "&TEXT($E9,"0")&" units. Please confirm availability and your fastest lead time. Thank you - Momentum Mind Store."," ","%20"),"💬 ORDER NOW"),"")) | H9: =IF($A9="","",IF($F9="⚠️ REORDER NOW",HYPERLINK("mailto:"&_xlfn.XLOOKUP($A9,'Item Master'!$A$4:$A$53,'Item Master'!$J$4:$J$53,"")&"?subject="&SUBSTITUTE("URGENT restock request - "&$B9&" ("&$A9&")"," ","%20")&"&body="&SUBSTITUTE(SUBSTITUTE("Hello "&_xlfn.XLOOKUP($A9,'Item Master'!$A$4:$A$53,'Item Master'!$H$4:$H$53,"Supplier")&"," & CHAR(10) & "We urgently need to restock "&$B9&" (SKU "&$A9&"). Our current stock is "&TEXT($E9,"0")&" units, which is below our reorder threshold." & CHAR(10) & "Please confirm availability, unit price and lead time by return." & CHAR(10) & "Kind regards," & CHAR(10) & "Momentum Mind Store"," ","%20"),CHAR(10),"%0D%0A"),"✉️ EMAIL"),"")) | I9: =IF($A9="","",$E9*_xlfn.XLOOKUP($A9,'Item Master'!$A$4:$A$53,'Item Master'!$D$4:$D$53,0))
A10: =IF(INDEX('Item Master'!$A$4:$A$53,2)="","",INDEX('Item Master'!$A$4:$A$53,2)) | B10: =IF($A10="","",_xlfn.XLOOKUP($A10,'Item Master'!$A$4:$A$53,'Item Master'!$B$4:$B$53,"")) | C10: =IF($A10="","",SUMIFS('Log Transaction'!$E$4:$E$303,'Log Transaction'!$C$4:$C$303,$A10,'Log Transaction'!$D$4:$D$303,"IN")) | D10: =IF($A10="","",SUMIFS('Log Transaction'!$E$4:$E$303,'Log Transaction'!$C$4:$C$303,$A10,'Log Transaction'!$D$4:$D$303,"OUT")+SUMIFS('Log Transaction'!$E$4:$E$303,'Log Transaction'!$C$4:$C$303,$A10,'Log Transaction'!$D$4:$D$303,"SHRINKAGE")) | E10: =IF($A10="","",$C10-$D10) | F10: =IF($A10="","",IF($E10<=_xlfn.XLOOKUP($A10,'Item Master'!$A$4:$A$53,'Item Master'!$F$4:$F$53,0)*0.1,"⚠️ REORDER NOW","✅ IN STOCK")) | G10: =IF($A10="","",IF($F10="⚠️ REORDER NOW",HYPERLINK("https://wa.me/"&SUBSTITUTE(SUBSTITUTE(SUBSTITUTE(SUBSTITUTE(SUBSTITUTE(SUBSTITUTE(_xlfn.XLOOKUP($A10,'Item Master'!$A$4:$A$53,'Item Master'!$I$4:$I$53,""),"+",""),"-","")," ",""),"(",""),")",""),".","")&"?text="&SUBSTITUTE("Hello "&_xlfn.XLOOKUP($A10,'Item Master'!$A$4:$A$53,'Item Master'!$H$4:$H$53,"Supplier")&", we urgently need more "&$B10&". Current stock is only "&TEXT($E10,"0")&" units. Please confirm availability and your fastest lead time. Thank you - Momentum Mind Store."," ","%20"),"💬 ORDER NOW"),"")) | H10: =IF($A10="","",IF($F10="⚠️ REORDER NOW",HYPERLINK("mailto:"&_xlfn.XLOOKUP($A10,'Item Master'!$A$4:$A$53,'Item Master'!$J$4:$J$53,"")&"?subject="&SUBSTITUTE("URGENT restock request - "&$B10&" ("&$A10&")"," ","%20")&"&body="&SUBSTITUTE(SUBSTITUTE("Hello "&_xlfn.XLOOKUP($A10,'Item Master'!$A$4:$A$53,'Item Master'!$H$4:$H$53,"Supplier")&"," & CHAR(10) & "We urgently need to restock "&$B10&" (SKU "&$A10&"). Our current stock is "&TEXT($E10,"0")&" units, which is below our reorder threshold." & CHAR(10) & "Please confirm availability, unit price and lead time by return." & CHAR(10) & "Kind regards," & CHAR(10) & "Momentum Mind Store"," ","%20"),CHAR(10),"%0D%0A"),"✉️ EMAIL"),"")) | I10: =IF($A10="","",$E10*_xlfn.XLOOKUP($A10,'Item Master'!$A$4:$A$53,'Item Master'!$D$4:$D$53,0))
A11: =IF(INDEX('Item Master'!$A$4:$A$53,3)="","",INDEX('Item Master'!$A$4:$A$53,3)) | B11: =IF($A11="","",_xlfn.XLOOKUP($A11,'Item Master'!$A$4:$A$53,'Item Master'!$B$4:$B$53,"")) | C11: =IF($A11="","",SUMIFS('Log Transaction'!$E$4:$E$303,'Log Transaction'!$C$4:$C$303,$A11,'Log Transaction'!$D$4:$D$303,"IN")) | D11: =IF($A11="","",SUMIFS('Log Transaction'!$E$4:$E$303,'Log Transaction'!$C$4:$C$303,$A11,'Log Transaction'!$D$4:$D$303,"OUT")+SUMIFS('Log Transaction'!$E$4:$E$303,'Log Transaction'!$C$4:$C$303,$A11,'Log Transaction'!$D$4:$D$303,"SHRINKAGE")) | E11: =IF($A11="","",$C11-$D11) | F11: =IF($A11="","",IF($E11<=_xlfn.XLOOKUP($A11,'Item Master'!$A$4:$A$53,'Item Master'!$F$4:$F$53,0)*0.1,"⚠️ REORDER NOW","✅ IN STOCK")) | G11: =IF($A11="","",IF($F11="⚠️ REORDER NOW",HYPERLINK("https://wa.me/"&SUBSTITUTE(SUBSTITUTE(SUBSTITUTE(SUBSTITUTE(SUBSTITUTE(SUBSTITUTE(_xlfn.XLOOKUP($A11,'Item Master'!$A$4:$A$53,'Item Master'!$I$4:$I$53,""),"+",""),"-","")," ",""),"(",""),")",""),".","")&"?text="&SUBSTITUTE("Hello "&_xlfn.XLOOKUP($A11,'Item Master'!$A$4:$A$53,'Item Master'!$H$4:$H$53,"Supplier")&", we urgently need more "&$B11&". Current stock is only "&TEXT($E11,"0")&" units. Please confirm availability and your fastest lead time. Thank you - Momentum Mind Store."," ","%20"),"💬 ORDER NOW"),"")) | H11: =IF($A11="","",IF($F11="⚠️ REORDER NOW",HYPERLINK("mailto:"&_xlfn.XLOOKUP($A11,'Item Master'!$A$4:$A$53,'Item Master'!$J$4:$J$53,"")&"?subject="&SUBSTITUTE("URGENT restock request - "&$B11&" ("&$A11&")"," ","%20")&"&body="&SUBSTITUTE(SUBSTITUTE("Hello "&_xlfn.XLOOKUP($A11,'Item Master'!$A$4:$A$53,'Item Master'!$H$4:$H$53,"Supplier")&"," & CHAR(10) & "We urgently need to restock "&$B11&" (SKU "&$A11&"). Our current stock is "&TEXT($E11,"0")&" units, which is below our reorder threshold." & CHAR(10) & "Please confirm availability, unit price and lead time by return." & CHAR(10) & "Kind regards," & CHAR(10) & "Momentum Mind Store"," ","%20"),CHAR(10),"%0D%0A"),"✉️ EMAIL"),"")) | I11: =IF($A11="","",$E11*_xlfn.XLOOKUP($A11,'Item Master'!$A$4:$A$53,'Item Master'!$D$4:$D$53,0))
A12: =IF(INDEX('Item Master'!$A$4:$A$53,4)="","",INDEX('Item Master'!$A$4:$A$53,4)) | B12: =IF($A12="","",_xlfn.XLOOKUP($A12,'Item Master'!$A$4:$A$53,'Item Master'!$B$4:$B$53,"")) | C12: =IF($A12="","",SUMIFS('Log Transaction'!$E$4:$E$303,'Log Transaction'!$C$4:$C$303,$A12,'Log Transaction'!$D$4:$D$303,"IN")) | D12: =IF($A12="","",SUMIFS('Log Transaction'!$E$4:$E$303,'Log Transaction'!$C$4:$C$303,$A12,'Log Transaction'!$D$4:$D$303,"OUT")+SUMIFS('Log Transaction'!$E$4:$E$303,'Log Transaction'!$C$4:$C$303,$A12,'Log Transaction'!$D$4:$D$303,"SHRINKAGE")) | E12: =IF($A12="","",$C12-$D12) | F12: =IF($A12="","",IF($E12<=_xlfn.XLOOKUP($A12,'Item Master'!$A$4:$A$53,'Item Master'!$F$4:$F$53,0)*0.1,"⚠️ REORDER NOW","✅ IN STOCK")) | G12: =IF($A12="","",IF($F12="⚠️ REORDER NOW",HYPERLINK("https://wa.me/"&SUBSTITUTE(SUBSTITUTE(SUBSTITUTE(SUBSTITUTE(SUBSTITUTE(SUBSTITUTE(_xlfn.XLOOKUP($A12,'Item Master'!$A$4:$A$53,'Item Master'!$I$4:$I$53,""),"+",""),"-","")," ",""),"(",""),")",""),".","")&"?text="&SUBSTITUTE("Hello "&_xlfn.XLOOKUP($A12,'Item Master'!$A$4:$A$53,'Item Master'!$H$4:$H$53,"Supplier")&", we urgently need more "&$B12&". Current stock is only "&TEXT($E12,"0")&" units. Please confirm availability and your fastest lead time. Thank you - Momentum Mind Store."," ","%20"),"💬 ORDER NOW"),"")) | H12: =IF($A12="","",IF($F12="⚠️ REORDER NOW",HYPERLINK("mailto:"&_xlfn.XLOOKUP($A12,'Item Master'!$A$4:$A$53,'Item Master'!$J$4:$J$53,"")&"?subject="&SUBSTITUTE("URGENT restock request - "&$B12&" ("&$A12&")"," ","%20")&"&body="&SUBSTITUTE(SUBSTITUTE("Hello "&_xlfn.XLOOKUP($A12,'Item Master'!$A$4:$A$53,'Item Master'!$H$4:$H$53,"Supplier")&"," & CHAR(10) & "We urgently need to restock "&$B12&" (SKU "&$A12&"). Our current stock is "&TEXT($E12,"0")&" units, which is below our reorder threshold." & CHAR(10) & "Please confirm availability, unit price and lead time by return." & CHAR(10) & "Kind regards," & CHAR(10) & "Momentum Mind Store"," ","%20"),CHAR(10),"%0D%0A"),"✉️ EMAIL"),"")) | I12: =IF($A12="","",$E12*_xlfn.XLOOKUP($A12,'Item Master'!$A$4:$A$53,'Item Master'!$D$4:$D$53,0))
A13: =IF(INDEX('Item Master'!$A$4:$A$53,5)="","",INDEX('Item Master'!$A$4:$A$53,5)) | B13: =IF($A13="","",_xlfn.XLOOKUP($A13,'Item Master'!$A$4:$A$53,'Item Master'!$B$4:$B$53,"")) | C13: =IF($A13="","",SUMIFS('Log Transaction'!$E$4:$E$303,'Log Transaction'!$C$4:$C$303,$A13,'Log Transaction'!$D$4:$D$303,"IN")) | D13: =IF($A13="","",SUMIFS('Log Transaction'!$E$4:$E$303,'Log Transaction'!$C$4:$C$303,$A13,'Log Transaction'!$D$4:$D$303,"OUT")+SUMIFS('Log Transaction'!$E$4:$E$303,'Log Transaction'!$C$4:$C$303,$A13,'Log Transaction'!$D$4:$D$303,"SHRINKAGE")) | E13: =IF($A13="","",$C13-$D13) | F13: =IF($A13="","",IF($E13<=_xlfn.XLOOKUP($A13,'Item Master'!$A$4:$A$53,'Item Master'!$F$4:$F$53,0)*0.1,"⚠️ REORDER NOW","✅ IN STOCK")) | G13: =IF($A13="","",IF($F13="⚠️ REORDER NOW",HYPERLINK("https://wa.me/"&SUBSTITUTE(SUBSTITUTE(SUBSTITUTE(SUBSTITUTE(SUBSTITUTE(SUBSTITUTE(_xlfn.XLOOKUP($A13,'Item Master'!$A$4:$A$53,'Item Master'!$I$4:$I$53,""),"+",""),"-","")," ",""),"(",""),")",""),".","")&"?text="&SUBSTITUTE("Hello "&_xlfn.XLOOKUP($A13,'Item Master'!$A$4:$A$53,'Item Master'!$H$4:$H$53,"Supplier")&", we urgently need more "&$B13&". Current stock is only "&TEXT($E13,"0")&" units. Please confirm availability and your fastest lead time. Thank you - Momentum Mind Store."," ","%20"),"💬 ORDER NOW"),"")) | H13: =IF($A13="","",IF($F13="⚠️ REORDER NOW",HYPERLINK("mailto:"&_xlfn.XLOOKUP($A13,'Item Master'!$A$4:$A$53,'Item Master'!$J$4:$J$53,"")&"?subject="&SUBSTITUTE("URGENT restock request - "&$B13&" ("&$A13&")"," ","%20")&"&body="&SUBSTITUTE(SUBSTITUTE("Hello "&_xlfn.XLOOKUP($A13,'Item Master'!$A$4:$A$53,'Item Master'!$H$4:$H$53,"Supplier")&"," & CHAR(10) & "We urgently need to restock "&$B13&" (SKU "&$A13&"). Our current stock is "&TEXT($E13,"0")&" units, which is below our reorder threshold." & CHAR(10) & "Please confirm availability, unit price and lead time by return." & CHAR(10) & "Kind regards," & CHAR(10) & "Momentum Mind Store"," ","%20"),CHAR(10),"%0D%0A"),"✉️ EMAIL"),"")) | I13: =IF($A13="","",$E13*_xlfn.XLOOKUP($A13,'Item Master'!$A$4:$A$53,'Item Master'!$D$4:$D$53,0))
A14: =IF(INDEX('Item Master'!$A$4:$A$53,6)="","",INDEX('Item Master'!$A$4:$A$53,6)) | B14: =IF($A14="","",_xlfn.XLOOKUP($A14,'Item Master'!$A$4:$A$53,'Item Master'!$B$4:$B$53,"")) | C14: =IF($A14="","",SUMIFS('Log Transaction'!$E$4:$E$303,'Log Transaction'!$C$4:$C$303,$A14,'Log Transaction'!$D$4:$D$303,"IN")) | D14: =IF($A14="","",SUMIFS('Log Transaction'!$E$4:$E$303,'Log Transaction'!$C$4:$C$303,$A14,'Log Transaction'!$D$4:$D$303,"OUT")+SUMIFS('Log Transaction'!$E$4:$E$303,'Log Transaction'!$C$4:$C$303,$A14,'Log Transaction'!$D$4:$D$303,"SHRINKAGE")) | E14: =IF($A14="","",$C14-$D14) | F14: =IF($A14="","",IF($E14<=_xlfn.XLOOKUP($A14,'Item Master'!$A$4:$A$53,'Item Master'!$F$4:$F$53,0)*0.1,"⚠️ REORDER NOW","✅ IN STOCK")) | G14: =IF($A14="","",IF($F14="⚠️ REORDER NOW",HYPERLINK("https://wa.me/"&SUBSTITUTE(SUBSTITUTE(SUBSTITUTE(SUBSTITUTE(SUBSTITUTE(SUBSTITUTE(_xlfn.XLOOKUP($A14,'Item Master'!$A$4:$A$53,'Item Master'!$I$4:$I$53,""),"+",""),"-","")," ",""),"(",""),")",""),".","")&"?text="&SUBSTITUTE("Hello "&_xlfn.XLOOKUP($A14,'Item Master'!$A$4:$A$53,'Item Master'!$H$4:$H$53,"Supplier")&", we urgently need more "&$B14&". Current stock is only "&TEXT($E14,"0")&" units. Please confirm availability and your fastest lead time. Thank you - Momentum Mind Store."," ","%20"),"💬 ORDER NOW"),"")) | H14: =IF($A14="","",IF($F14="⚠️ REORDER NOW",HYPERLINK("mailto:"&_xlfn.XLOOKUP($A14,'Item Master'!$A$4:$A$53,'Item Master'!$J$4:$J$53,"")&"?subject="&SUBSTITUTE("URGENT restock request - "&$B14&" ("&$A14&")"," ","%20")&"&body="&SUBSTITUTE(SUBSTITUTE("Hello "&_xlfn.XLOOKUP($A14,'Item Master'!$A$4:$A$53,'Item Master'!$H$4:$H$53,"Supplier")&"," & CHAR(10) & "We urgently need to restock "&$B14&" (SKU "&$A14&"). Our current stock is "&TEXT($E14,"0")&" units, which is below our reorder threshold." & CHAR(10) & "Please confirm availability, unit price and lead time by return." & CHAR(10) & "Kind regards," & CHAR(10) & "Momentum Mind Store"," ","%20"),CHAR(10),"%0D%0A"),"✉️ EMAIL"),"")) | I14: =IF($A14="","",$E14*_xlfn.XLOOKUP($A14,'Item Master'!$A$4:$A$53,'Item Master'!$D$4:$D$53,0))
A15: =IF(INDEX('Item Master'!$A$4:$A$53,7)="","",INDEX('Item Master'!$A$4:$A$53,7)) | B15: =IF($A15="","",_xlfn.XLOOKUP($A15,'Item Master'!$A$4:$A$53,'Item Master'!$B$4:$B$53,"")) | C15: =IF($A15="","",SUMIFS('Log Transaction'!$E$4:$E$303,'Log Transaction'!$C$4:$C$303,$A15,'Log Transaction'!$D$4:$D$303,"IN")) | D15: =IF($A15="","",SUMIFS('Log Transaction'!$E$4:$E$303,'Log Transaction'!$C$4:$C$303,$A15,'Log Transaction'!$D$4:$D$303,"OUT")+SUMIFS('Log Transaction'!$E$4:$E$303,'Log Transaction'!$C$4:$C$303,$A15,'Log Transaction'!$D$4:$D$303,"SHRINKAGE")) | E15: =IF($A15="","",$C15-$D15) | F15: =IF($A15="","",IF($E15<=_xlfn.XLOOKUP($A15,'Item Master'!$A$4:$A$53,'Item Master'!$F$4:$F$53,0)*0.1,"⚠️ REORDER NOW","✅ IN STOCK")) | G15: =IF($A15="","",IF($F15="⚠️ REORDER NOW",HYPERLINK("https://wa.me/"&SUBSTITUTE(SUBSTITUTE(SUBSTITUTE(SUBSTITUTE(SUBSTITUTE(SUBSTITUTE(_xlfn.XLOOKUP($A15,'Item Master'!$A$4:$A$53,'Item Master'!$I$4:$I$53,""),"+",""),"-","")," ",""),"(",""),")",""),".","")&"?text="&SUBSTITUTE("Hello "&_xlfn.XLOOKUP($A15,'Item Master'!$A$4:$A$53,'Item Master'!$H$4:$H$53,"Supplier")&", we urgently need more "&$B15&". Current stock is only "&TEXT($E15,"0")&" units. Please confirm availability and your fastest lead time. Thank you - Momentum Mind Store."," ","%20"),"💬 ORDER NOW"),"")) | H15: =IF($A15="","",IF($F15="⚠️ REORDER NOW",HYPERLINK("mailto:"&_xlfn.XLOOKUP($A15,'Item Master'!$A$4:$A$53,'Item Master'!$J$4:$J$53,"")&"?subject="&SUBSTITUTE("URGENT restock request - "&$B15&" ("&$A15&")"," ","%20")&"&body="&SUBSTITUTE(SUBSTITUTE("Hello "&_xlfn.XLOOKUP($A15,'Item Master'!$A$4:$A$53,'Item Master'!$H$4:$H$53,"Supplier")&"," & CHAR(10) & "We urgently need to restock "&$B15&" (SKU "&$A15&"). Our current stock is "&TEXT($E15,"0")&" units, which is below our reorder threshold." & CHAR(10) & "Please confirm availability, unit price and lead time by return." & CHAR(10) & "Kind regards," & CHAR(10) & "Momentum Mind Store"," ","%20"),CHAR(10),"%0D%0A"),"✉️ EMAIL"),"")) | I15: =IF($A15="","",$E15*_xlfn.XLOOKUP($A15,'Item Master'!$A$4:$A$53,'Item Master'!$D$4:$D$53,0))
A16: =IF(INDEX('Item Master'!$A$4:$A$53,8)="","",INDEX('Item Master'!$A$4:$A$53,8)) | B16: =IF($A16="","",_xlfn.XLOOKUP($A16,'Item Master'!$A$4:$A$53,'Item Master'!$B$4:$B$53,"")) | C16: =IF($A16="","",SUMIFS('Log Transaction'!$E$4:$E$303,'Log Transaction'!$C$4:$C$303,$A16,'Log Transaction'!$D$4:$D$303,"IN")) | D16: =IF($A16="","",SUMIFS('Log Transaction'!$E$4:$E$303,'Log Transaction'!$C$4:$C$303,$A16,'Log Transaction'!$D$4:$D$303,"OUT")+SUMIFS('Log Transaction'!$E$4:$E$303,'Log Transaction'!$C$4:$C$303,$A16,'Log Transaction'!$D$4:$D$303,"SHRINKAGE")) | E16: =IF($A16="","",$C16-$D16) | F16: =IF($A16="","",IF($E16<=_xlfn.XLOOKUP($A16,'Item Master'!$A$4:$A$53,'Item Master'!$F$4:$F$53,0)*0.1,"⚠️ REORDER NOW","✅ IN STOCK")) | G16: =IF($A16="","",IF($F16="⚠️ REORDER NOW",HYPERLINK("https://wa.me/"&SUBSTITUTE(SUBSTITUTE(SUBSTITUTE(SUBSTITUTE(SUBSTITUTE(SUBSTITUTE(_xlfn.XLOOKUP($A16,'Item Master'!$A$4:$A$53,'Item Master'!$I$4:$I$53,""),"+",""),"-","")," ",""),"(",""),")",""),".","")&"?text="&SUBSTITUTE("Hello "&_xlfn.XLOOKUP($A16,'Item Master'!$A$4:$A$53,'Item Master'!$H$4:$H$53,"Supplier")&", we urgently need more "&$B16&". Current stock is only "&TEXT($E16,"0")&" units. Please confirm availability and your fastest lead time. Thank you - Momentum Mind Store."," ","%20"),"💬 ORDER NOW"),"")) | H16: =IF($A16="","",IF($F16="⚠️ REORDER NOW",HYPERLINK("mailto:"&_xlfn.XLOOKUP($A16,'Item Master'!$A$4:$A$53,'Item Master'!$J$4:$J$53,"")&"?subject="&SUBSTITUTE("URGENT restock request - "&$B16&" ("&$A16&")"," ","%20")&"&body="&SUBSTITUTE(SUBSTITUTE("Hello "&_xlfn.XLOOKUP($A16,'Item Master'!$A$4:$A$53,'Item Master'!$H$4:$H$53,"Supplier")&"," & CHAR(10) & "We urgently need to restock "&$B16&" (SKU "&$A16&"). Our current stock is "&TEXT($E16,"0")&" units, which is below our reorder threshold." & CHAR(10) & "Please confirm availability, unit price and lead time by return." & CHAR(10) & "Kind regards," & CHAR(10) & "Momentum Mind Store"," ","%20"),CHAR(10),"%0D%0A"),"✉️ EMAIL"),"")) | I16: =IF($A16="","",$E16*_xlfn.XLOOKUP($A16,'Item Master'!$A$4:$A$53,'Item Master'!$D$4:$D$53,0))
A17: =IF(INDEX('Item Master'!$A$4:$A$53,9)="","",INDEX('Item Master'!$A$4:$A$53,9)) | B17: =IF($A17="","",_xlfn.XLOOKUP($A17,'Item Master'!$A$4:$A$53,'Item Master'!$B$4:$B$53,"")) | C17: =IF($A17="","",SUMIFS('Log Transaction'!$E$4:$E$303,'Log Transaction'!$C$4:$C$303,$A17,'Log Transaction'!$D$4:$D$303,"IN")) | D17: =IF($A17="","",SUMIFS('Log Transaction'!$E$4:$E$303,'Log Transaction'!$C$4:$C$303,$A17,'Log Transaction'!$D$4:$D$303,"OUT")+SUMIFS('Log Transaction'!$E$4:$E$303,'Log Transaction'!$C$4:$C$303,$A17,'Log Transaction'!$D$4:$D$303,"SHRINKAGE")) | E17: =IF($A17="","",$C17-$D17) | F17: =IF($A17="","",IF($E17<=_xlfn.XLOOKUP($A17,'Item Master'!$A$4:$A$53,'Item Master'!$F$4:$F$53,0)*0.1,"⚠️ REORDER NOW","✅ IN STOCK")) | G17: =IF($A17="","",IF($F17="⚠️ REORDER NOW",HYPERLINK("https://wa.me/"&SUBSTITUTE(SUBSTITUTE(SUBSTITUTE(SUBSTITUTE(SUBSTITUTE(SUBSTITUTE(_xlfn.XLOOKUP($A17,'Item Master'!$A$4:$A$53,'Item Master'!$I$4:$I$53,""),"+",""),"-","")," ",""),"(",""),")",""),".","")&"?text="&SUBSTITUTE("Hello "&_xlfn.XLOOKUP($A17,'Item Master'!$A$4:$A$53,'Item Master'!$H$4:$H$53,"Supplier")&", we urgently need more "&$B17&". Current stock is only "&TEXT($E17,"0")&" units. Please confirm availability and your fastest lead time. Thank you - Momentum Mind Store."," ","%20"),"💬 ORDER NOW"),"")) | H17: =IF($A17="","",IF($F17="⚠️ REORDER NOW",HYPERLINK("mailto:"&_xlfn.XLOOKUP($A17,'Item Master'!$A$4:$A$53,'Item Master'!$J$4:$J$53,"")&"?subject="&SUBSTITUTE("URGENT restock request - "&$B17&" ("&$A17&")"," ","%20")&"&body="&SUBSTITUTE(SUBSTITUTE("Hello "&_xlfn.XLOOKUP($A17,'Item Master'!$A$4:$A$53,'Item Master'!$H$4:$H$53,"Supplier")&"," & CHAR(10) & "We urgently need to restock "&$B17&" (SKU "&$A17&"). Our current stock is "&TEXT($E17,"0")&" units, which is below our reorder threshold." & CHAR(10) & "Please confirm availability, unit price and lead time by return." & CHAR(10) & "Kind regards," & CHAR(10) & "Momentum Mind Store"," ","%20"),CHAR(10),"%0D%0A"),"✉️ EMAIL"),"")) | I17: =IF($A17="","",$E17*_xlfn.XLOOKUP($A17,'Item Master'!$A$4:$A$53,'Item Master'!$D$4:$D$53,0))
A18: =IF(INDEX('Item Master'!$A$4:$A$53,10)="","",INDEX('Item Master'!$A$4:$A$53,10)) | B18: =IF($A18="","",_xlfn.XLOOKUP($A18,'Item Master'!$A$4:$A$53,'Item Master'!$B$4:$B$53,"")) | C18: =IF($A18="","",SUMIFS('Log Transaction'!$E$4:$E$303,'Log Transaction'!$C$4:$C$303,$A18,'Log Transaction'!$D$4:$D$303,"IN")) | D18: =IF($A18="","",SUMIFS('Log Transaction'!$E$4:$E$303,'Log Transaction'!$C$4:$C$303,$A18,'Log Transaction'!$D$4:$D$303,"OUT")+SUMIFS('Log Transaction'!$E$4:$E$303,'Log Transaction'!$C$4:$C$303,$A18,'Log Transaction'!$D$4:$D$303,"SHRINKAGE")) | E18: =IF($A18="","",$C18-$D18) | F18: =IF($A18="","",IF($E18<=_xlfn.XLOOKUP($A18,'Item Master'!$A$4:$A$53,'Item Master'!$F$4:$F$53,0)*0.1,"⚠️ REORDER NOW","✅ IN STOCK")) | G18: =IF($A18="","",IF($F18="⚠️ REORDER NOW",HYPERLINK("https://wa.me/"&SUBSTITUTE(SUBSTITUTE(SUBSTITUTE(SUBSTITUTE(SUBSTITUTE(SUBSTITUTE(_xlfn.XLOOKUP($A18,'Item Master'!$A$4:$A$53,'Item Master'!$I$4:$I$53,""),"+",""),"-","")," ",""),"(",""),")",""),".","")&"?text="&SUBSTITUTE("Hello "&_xlfn.XLOOKUP($A18,'Item Master'!$A$4:$A$53,'Item Master'!$H$4:$H$53,"Supplier")&", we urgently need more "&$B18&". Current stock is only "&TEXT($E18,"0")&" units. Please confirm availability and your fastest lead time. Thank you - Momentum Mind Store."," ","%20"),"💬 ORDER NOW"),"")) | H18: =IF($A18="","",IF($F18="⚠️ REORDER NOW",HYPERLINK("mailto:"&_xlfn.XLOOKUP($A18,'Item Master'!$A$4:$A$53,'Item Master'!$J$4:$J$53,"")&"?subject="&SUBSTITUTE("URGENT restock request - "&$B18&" ("&$A18&")"," ","%20")&"&body="&SUBSTITUTE(SUBSTITUTE("Hello "&_xlfn.XLOOKUP($A18,'Item Master'!$A$4:$A$53,'Item Master'!$H$4:$H$53,"Supplier")&"," & CHAR(10) & "We urgently need to restock "&$B18&" (SKU "&$A18&"). Our current stock is "&TEXT($E18,"0")&" units, which is below our reorder threshold." & CHAR(10) & "Please confirm availability, unit price and lead time by return." & CHAR(10) & "Kind regards," & CHAR(10) & "Momentum Mind Store"," ","%20"),CHAR(10),"%0D%0A"),"✉️ EMAIL"),"")) | I18: =IF($A18="","",$E18*_xlfn.XLOOKUP($A18,'Item Master'!$A$4:$A$53,'Item Master'!$D$4:$D$53,0))
A19: =IF(INDEX('Item Master'!$A$4:$A$53,11)="","",INDEX('Item Master'!$A$4:$A$53,11)) | B19: =IF($A19="","",_xlfn.XLOOKUP($A19,'Item Master'!$A$4:$A$53,'Item Master'!$B$4:$B$53,"")) | C19: =IF($A19="","",SUMIFS('Log Transaction'!$E$4:$E$303,'Log Transaction'!$C$4:$C$303,$A19,'Log Transaction'!$D$4:$D$303,"IN")) | D19: =IF($A19="","",SUMIFS('Log Transaction'!$E$4:$E$303,'Log Transaction'!$C$4:$C$303,$A19,'Log Transaction'!$D$4:$D$303,"OUT")+SUMIFS('Log Transaction'!$E$4:$E$303,'Log Transaction'!$C$4:$C$303,$A19,'Log Transaction'!$D$4:$D$303,"SHRINKAGE")) | E19: =IF($A19="","",$C19-$D19) | F19: =IF($A19="","",IF($E19<=_xlfn.XLOOKUP($A19,'Item Master'!$A$4:$A$53,'Item Master'!$F$4:$F$53,0)*0.1,"⚠️ REORDER NOW","✅ IN STOCK")) | G19: =IF($A19="","",IF($F19="⚠️ REORDER NOW",HYPERLINK("https://wa.me/"&SUBSTITUTE(SUBSTITUTE(SUBSTITUTE(SUBSTITUTE(SUBSTITUTE(SUBSTITUTE(_xlfn.XLOOKUP($A19,'Item Master'!$A$4:$A$53,'Item Master'!$I$4:$I$53,""),"+",""),"-","")," ",""),"(",""),")",""),".","")&"?text="&SUBSTITUTE("Hello "&_xlfn.XLOOKUP($A19,'Item Master'!$A$4:$A$53,'Item Master'!$H$4:$H$53,"Supplier")&", we urgently need more "&$B19&". Current stock is only "&TEXT($E19,"0")&" units. Please confirm availability and your fastest lead time. Thank you - Momentum Mind Store."," ","%20"),"💬 ORDER NOW"),"")) | H19: =IF($A19="","",IF($F19="⚠️ REORDER NOW",HYPERLINK("mailto:"&_xlfn.XLOOKUP($A19,'Item Master'!$A$4:$A$53,'Item Master'!$J$4:$J$53,"")&"?subject="&SUBSTITUTE("URGENT restock request - "&$B19&" ("&$A19&")"," ","%20")&"&body="&SUBSTITUTE(SUBSTITUTE("Hello "&_xlfn.XLOOKUP($A19,'Item Master'!$A$4:$A$53,'Item Master'!$H$4:$H$53,"Supplier")&"," & CHAR(10) & "We urgently need to restock "&$B19&" (SKU "&$A19&"). Our current stock is "&TEXT($E19,"0")&" units, which is below our reorder threshold." & CHAR(10) & "Please confirm availability, unit price and lead time by return." & CHAR(10) & "Kind regards," & CHAR(10) & "Momentum Mind Store"," ","%20"),CHAR(10),"%0D%0A"),"✉️ EMAIL"),"")) | I19: =IF($A19="","",$E19*_xlfn.XLOOKUP($A19,'Item Master'!$A$4:$A$53,'Item Master'!$D$4:$D$53,0))
A20: =IF(INDEX('Item Master'!$A$4:$A$53,12)="","",INDEX('Item Master'!$A$4:$A$53,12)) | B20: =IF($A20="","",_xlfn.XLOOKUP($A20,'Item Master'!$A$4:$A$53,'Item Master'!$B$4:$B$53,"")) | C20: =IF($A20="","",SUMIFS('Log Transaction'!$E$4:$E$303,'Log Transaction'!$C$4:$C$303,$A20,'Log Transaction'!$D$4:$D$303,"IN")) | D20: =IF($A20="","",SUMIFS('Log Transaction'!$E$4:$E$303,'Log Transaction'!$C$4:$C$303,$A20,'Log Transaction'!$D$4:$D$303,"OUT")+SUMIFS('Log Transaction'!$E$4:$E$303,'Log Transaction'!$C$4:$C$303,$A20,'Log Transaction'!$D$4:$D$303,"SHRINKAGE")) | E20: =IF($A20="","",$C20-$D20) | F20: =IF($A20="","",IF($E20<=_xlfn.XLOOKUP($A20,'Item Master'!$A$4:$A$53,'Item Master'!$F$4:$F$53,0)*0.1,"⚠️ REORDER NOW","✅ IN STOCK")) | G20: =IF($A20="","",IF($F20="⚠️ REORDER NOW",HYPERLINK("https://wa.me/"&SUBSTITUTE(SUBSTITUTE(SUBSTITUTE(SUBSTITUTE(SUBSTITUTE(SUBSTITUTE(_xlfn.XLOOKUP($A20,'Item Master'!$A$4:$A$53,'Item Master'!$I$4:$I$53,""),"+",""),"-","")," ",""),"(",""),")",""),".","")&"?text="&SUBSTITUTE("Hello "&_xlfn.XLOOKUP($A20,'Item Master'!$A$4:$A$53,'Item Master'!$H$4:$H$53,"Supplier")&", we urgently need more "&$B20&". Current stock is only "&TEXT($E20,"0")&" units. Please confirm availability and your fastest lead time. Thank you - Momentum Mind Store."," ","%20"),"💬 ORDER NOW"),"")) | H20: =IF($A20="","",IF($F20="⚠️ REORDER NOW",HYPERLINK("mailto:"&_xlfn.XLOOKUP($A20,'Item Master'!$A$4:$A$53,'Item Master'!$J$4:$J$53,"")&"?subject="&SUBSTITUTE("URGENT restock request - "&$B20&" ("&$A20&")"," ","%20")&"&body="&SUBSTITUTE(SUBSTITUTE("Hello "&_xlfn.XLOOKUP($A20,'Item Master'!$A$4:$A$53,'Item Master'!$H$4:$H$53,"Supplier")&"," & CHAR(10) & "We urgently need to restock "&$B20&" (SKU "&$A20&"). Our current stock is "&TEXT($E20,"0")&" units, which is below our reorder threshold." & CHAR(10) & "Please confirm availability, unit price and lead time by return." & CHAR(10) & "Kind regards," & CHAR(10) & "Momentum Mind Store"," ","%20"),CHAR(10),"%0D%0A"),"✉️ EMAIL"),"")) | I20: =IF($A20="","",$E20*_xlfn.XLOOKUP($A20,'Item Master'!$A$4:$A$53,'Item Master'!$D$4:$D$53,0))
A21: =IF(INDEX('Item Master'!$A$4:$A$53,13)="","",INDEX('Item Master'!$A$4:$A$53,13)) | B21: =IF($A21="","",_xlfn.XLOOKUP($A21,'Item Master'!$A$4:$A$53,'Item Master'!$B$4:$B$53,"")) | C21: =IF($A21="","",SUMIFS('Log Transaction'!$E$4:$E$303,'Log Transaction'!$C$4:$C$303,$A21,'Log Transaction'!$D$4:$D$303,"IN")) | D21: =IF($A21="","",SUMIFS('Log Transaction'!$E$4:$E$303,'Log Transaction'!$C$4:$C$303,$A21,'Log Transaction'!$D$4:$D$303,"OUT")+SUMIFS('Log Transaction'!$E$4:$E$303,'Log Transaction'!$C$4:$C$303,$A21,'Log Transaction'!$D$4:$D$303,"SHRINKAGE")) | E21: =IF($A21="","",$C21-$D21) | F21: =IF($A21="","",IF($E21<=_xlfn.XLOOKUP($A21,'Item Master'!$A$4:$A$53,'Item Master'!$F$4:$F$53,0)*0.1,"⚠️ REORDER NOW","✅ IN STOCK")) | G21: =IF($A21="","",IF($F21="⚠️ REORDER NOW",HYPERLINK("https://wa.me/"&SUBSTITUTE(SUBSTITUTE(SUBSTITUTE(SUBSTITUTE(SUBSTITUTE(SUBSTITUTE(_xlfn.XLOOKUP($A21,'Item Master'!$A$4:$A$53,'Item Master'!$I$4:$I$53,""),"+",""),"-","")," ",""),"(",""),")",""),".","")&"?text="&SUBSTITUTE("Hello "&_xlfn.XLOOKUP($A21,'Item Master'!$A$4:$A$53,'Item Master'!$H$4:$H$53,"Supplier")&", we urgently need more "&$B21&". Current stock is only "&TEXT($E21,"0")&" units. Please confirm availability and your fastest lead time. Thank you - Momentum Mind Store."," ","%20"),"💬 ORDER NOW"),"")) | H21: =IF($A21="","",IF($F21="⚠️ REORDER NOW",HYPERLINK("mailto:"&_xlfn.XLOOKUP($A21,'Item Master'!$A$4:$A$53,'Item Master'!$J$4:$J$53,"")&"?subject="&SUBSTITUTE("URGENT restock request - "&$B21&" ("&$A21&")"," ","%20")&"&body="&SUBSTITUTE(SUBSTITUTE("Hello "&_xlfn.XLOOKUP($A21,'Item Master'!$A$4:$A$53,'Item Master'!$H$4:$H$53,"Supplier")&"," & CHAR(10) & "We urgently need to restock "&$B21&" (SKU "&$A21&"). Our current stock is "&TEXT($E21,"0")&" units, which is below our reorder threshold." & CHAR(10) & "Please confirm availability, unit price and lead time by return." & CHAR(10) & "Kind regards," & CHAR(10) & "Momentum Mind Store"," ","%20"),CHAR(10),"%0D%0A"),"✉️ EMAIL"),"")) | I21: =IF($A21="","",$E21*_xlfn.XLOOKUP($A21,'Item Master'!$A$4:$A$53,'Item Master'!$D$4:$D$53,0))
A22: =IF(INDEX('Item Master'!$A$4:$A$53,14)="","",INDEX('Item Master'!$A$4:$A$53,14)) | B22: =IF($A22="","",_xlfn.XLOOKUP($A22,'Item Master'!$A$4:$A$53,'Item Master'!$B$4:$B$53,"")) | C22: =IF($A22="","",SUMIFS('Log Transaction'!$E$4:$E$303,'Log Transaction'!$C$4:$C$303,$A22,'Log Transaction'!$D$4:$D$303,"IN")) | D22: =IF($A22="","",SUMIFS('Log Transaction'!$E$4:$E$303,'Log Transaction'!$C$4:$C$303,$A22,'Log Transaction'!$D$4:$D$303,"OUT")+SUMIFS('Log Transaction'!$E$4:$E$303,'Log Transaction'!$C$4:$C$303,$A22,'Log Transaction'!$D$4:$D$303,"SHRINKAGE")) | E22: =IF($A22="","",$C22-$D22) | F22: =IF($A22="","",IF($E22<=_xlfn.XLOOKUP($A22,'Item Master'!$A$4:$A$53,'Item Master'!$F$4:$F$53,0)*0.1,"⚠️ REORDER NOW","✅ IN STOCK")) | G22: =IF($A22="","",IF($F22="⚠️ REORDER NOW",HYPERLINK("https://wa.me/"&SUBSTITUTE(SUBSTITUTE(SUBSTITUTE(SUBSTITUTE(SUBSTITUTE(SUBSTITUTE(_xlfn.XLOOKUP($A22,'Item Master'!$A$4:$A$53,'Item Master'!$I$4:$I$53,""),"+",""),"-","")," ",""),"(",""),")",""),".","")&"?text="&SUBSTITUTE("Hello "&_xlfn.XLOOKUP($A22,'Item Master'!$A$4:$A$53,'Item Master'!$H$4:$H$53,"Supplier")&", we urgently need more "&$B22&". Current stock is only "&TEXT($E22,"0")&" units. Please confirm availability and your fastest lead time. Thank you - Momentum Mind Store."," ","%20"),"💬 ORDER NOW"),"")) | H22: =IF($A22="","",IF($F22="⚠️ REORDER NOW",HYPERLINK("mailto:"&_xlfn.XLOOKUP($A22,'Item Master'!$A$4:$A$53,'Item Master'!$J$4:$J$53,"")&"?subject="&SUBSTITUTE("URGENT restock request - "&$B22&" ("&$A22&")"," ","%20")&"&body="&SUBSTITUTE(SUBSTITUTE("Hello "&_xlfn.XLOOKUP($A22,'Item Master'!$A$4:$A$53,'Item Master'!$H$4:$H$53,"Supplier")&"," & CHAR(10) & "We urgently need to restock "&$B22&" (SKU "&$A22&"). Our current stock is "&TEXT($E22,"0")&" units, which is below our reorder threshold." & CHAR(10) & "Please confirm availability, unit price and lead time by return." & CHAR(10) & "Kind regards," & CHAR(10) & "Momentum Mind Store"," ","%20"),CHAR(10),"%0D%0A"),"✉️ EMAIL"),"")) | I22: =IF($A22="","",$E22*_xlfn.XLOOKUP($A22,'Item Master'!$A$4:$A$53,'Item Master'!$D$4:$D$53,0))
A23: =IF(INDEX('Item Master'!$A$4:$A$53,15)="","",INDEX('Item Master'!$A$4:$A$53,15)) | B23: =IF($A23="","",_xlfn.XLOOKUP($A23,'Item Master'!$A$4:$A$53,'Item Master'!$B$4:$B$53,"")) | C23: =IF($A23="","",SUMIFS('Log Transaction'!$E$4:$E$303,'Log Transaction'!$C$4:$C$303,$A23,'Log Transaction'!$D$4:$D$303,"IN")) | D23: =IF($A23="","",SUMIFS('Log Transaction'!$E$4:$E$303,'Log Transaction'!$C$4:$C$303,$A23,'Log Transaction'!$D$4:$D$303,"OUT")+SUMIFS('Log Transaction'!$E$4:$E$303,'Log Transaction'!$C$4:$C$303,$A23,'Log Transaction'!$D$4:$D$303,"SHRINKAGE")) | E23: =IF($A23="","",$C23-$D23) | F23: =IF($A23="","",IF($E23<=_xlfn.XLOOKUP($A23,'Item Master'!$A$4:$A$53,'Item Master'!$F$4:$F$53,0)*0.1,"⚠️ REORDER NOW","✅ IN STOCK")) | G23: =IF($A23="","",IF($F23="⚠️ REORDER NOW",HYPERLINK("https://wa.me/"&SUBSTITUTE(SUBSTITUTE(SUBSTITUTE(SUBSTITUTE(SUBSTITUTE(SUBSTITUTE(_xlfn.XLOOKUP($A23,'Item Master'!$A$4:$A$53,'Item Master'!$I$4:$I$53,""),"+",""),"-","")," ",""),"(",""),")",""),".","")&"?text="&SUBSTITUTE("Hello "&_xlfn.XLOOKUP($A23,'Item Master'!$A$4:$A$53,'Item Master'!$H$4:$H$53,"Supplier")&", we urgently need more "&$B23&". Current stock is only "&TEXT($E23,"0")&" units. Please confirm availability and your fastest lead time. Thank you - Momentum Mind Store."," ","%20"),"💬 ORDER NOW"),"")) | H23: =IF($A23="","",IF($F23="⚠️ REORDER NOW",HYPERLINK("mailto:"&_xlfn.XLOOKUP($A23,'Item Master'!$A$4:$A$53,'Item Master'!$J$4:$J$53,"")&"?subject="&SUBSTITUTE("URGENT restock request - "&$B23&" ("&$A23&")"," ","%20")&"&body="&SUBSTITUTE(SUBSTITUTE("Hello "&_xlfn.XLOOKUP($A23,'Item Master'!$A$4:$A$53,'Item Master'!$H$4:$H$53,"Supplier")&"," & CHAR(10) & "We urgently need to restock "&$B23&" (SKU "&$A23&"). Our current stock is "&TEXT($E23,"0")&" units, which is below our reorder threshold." & CHAR(10) & "Please confirm availability, unit price and lead time by return." & CHAR(10) & "Kind regards," & CHAR(10) & "Momentum Mind Store"," ","%20"),CHAR(10),"%0D%0A"),"✉️ EMAIL"),"")) | I23: =IF($A23="","",$E23*_xlfn.XLOOKUP($A23,'Item Master'!$A$4:$A$53,'Item Master'!$D$4:$D$53,0))
A24: =IF(INDEX('Item Master'!$A$4:$A$53,16)="","",INDEX('Item Master'!$A$4:$A$53,16)) | B24: =IF($A24="","",_xlfn.XLOOKUP($A24,'Item Master'!$A$4:$A$53,'Item Master'!$B$4:$B$53,"")) | C24: =IF($A24="","",SUMIFS('Log Transaction'!$E$4:$E$303,'Log Transaction'!$C$4:$C$303,$A24,'Log Transaction'!$D$4:$D$303,"IN")) | D24: =IF($A24="","",SUMIFS('Log Transaction'!$E$4:$E$303,'Log Transaction'!$C$4:$C$303,$A24,'Log Transaction'!$D$4:$D$303,"OUT")+SUMIFS('Log Transaction'!$E$4:$E$303,'Log Transaction'!$C$4:$C$303,$A24,'Log Transaction'!$D$4:$D$303,"SHRINKAGE")) | E24: =IF($A24="","",$C24-$D24) | F24: =IF($A24="","",IF($E24<=_xlfn.XLOOKUP($A24,'Item Master'!$A$4:$A$53,'Item Master'!$F$4:$F$53,0)*0.1,"⚠️ REORDER NOW","✅ IN STOCK")) | G24: =IF($A24="","",IF($F24="⚠️ REORDER NOW",HYPERLINK("https://wa.me/"&SUBSTITUTE(SUBSTITUTE(SUBSTITUTE(SUBSTITUTE(SUBSTITUTE(SUBSTITUTE(_xlfn.XLOOKUP($A24,'Item Master'!$A$4:$A$53,'Item Master'!$I$4:$I$53,""),"+",""),"-","")," ",""),"(",""),")",""),".","")&"?text="&SUBSTITUTE("Hello "&_xlfn.XLOOKUP($A24,'Item Master'!$A$4:$A$53,'Item Master'!$H$4:$H$53,"Supplier")&", we urgently need more "&$B24&". Current stock is only "&TEXT($E24,"0")&" units. Please confirm availability and your fastest lead time. Thank you - Momentum Mind Store."," ","%20"),"💬 ORDER NOW"),"")) | H24: =IF($A24="","",IF($F24="⚠️ REORDER NOW",HYPERLINK("mailto:"&_xlfn.XLOOKUP($A24,'Item Master'!$A$4:$A$53,'Item Master'!$J$4:$J$53,"")&"?subject="&SUBSTITUTE("URGENT restock request - "&$B24&" ("&$A24&")"," ","%20")&"&body="&SUBSTITUTE(SUBSTITUTE("Hello "&_xlfn.XLOOKUP($A24,'Item Master'!$A$4:$A$53,'Item Master'!$H$4:$H$53,"Supplier")&"," & CHAR(10) & "We urgently need to restock "&$B24&" (SKU "&$A24&"). Our current stock is "&TEXT($E24,"0")&" units, which is below our reorder threshold." & CHAR(10) & "Please confirm availability, unit price and lead time by return." & CHAR(10) & "Kind regards," & CHAR(10) & "Momentum Mind Store"," ","%20"),CHAR(10),"%0D%0A"),"✉️ EMAIL"),"")) | I24: =IF($A24="","",$E24*_xlfn.XLOOKUP($A24,'Item Master'!$A$4:$A$53,'Item Master'!$D$4:$D$53,0))
A25: =IF(INDEX('Item Master'!$A$4:$A$53,17)="","",INDEX('Item Master'!$A$4:$A$53,17)) | B25: =IF($A25="","",_xlfn.XLOOKUP($A25,'Item Master'!$A$4:$A$53,'Item Master'!$B$4:$B$53,"")) | C25: =IF($A25="","",SUMIFS('Log Transaction'!$E$4:$E$303,'Log Transaction'!$C$4:$C$303,$A25,'Log Transaction'!$D$4:$D$303,"IN")) | D25: =IF($A25="","",SUMIFS('Log Transaction'!$E$4:$E$303,'Log Transaction'!$C$4:$C$303,$A25,'Log Transaction'!$D$4:$D$303,"OUT")+SUMIFS('Log Transaction'!$E$4:$E$303,'Log Transaction'!$C$4:$C$303,$A25,'Log Transaction'!$D$4:$D$303,"SHRINKAGE")) | E25: =IF($A25="","",$C25-$D25) | F25: =IF($A25="","",IF($E25<=_xlfn.XLOOKUP($A25,'Item Master'!$A$4:$A$53,'Item Master'!$F$4:$F$53,0)*0.1,"⚠️ REORDER NOW","✅ IN STOCK")) | G25: =IF($A25="","",IF($F25="⚠️ REORDER NOW",HYPERLINK("https://wa.me/"&SUBSTITUTE(SUBSTITUTE(SUBSTITUTE(SUBSTITUTE(SUBSTITUTE(SUBSTITUTE(_xlfn.XLOOKUP($A25,'Item Master'!$A$4:$A$53,'Item Master'!$I$4:$I$53,""),"+",""),"-","")," ",""),"(",""),")",""),".","")&"?text="&SUBSTITUTE("Hello "&_xlfn.XLOOKUP($A25,'Item Master'!$A$4:$A$53,'Item Master'!$H$4:$H$53,"Supplier")&", we urgently need more "&$B25&". Current stock is only "&TEXT($E25,"0")&" units. Please confirm availability and your fastest lead time. Thank you - Momentum Mind Store."," ","%20"),"💬 ORDER NOW"),"")) | H25: =IF($A25="","",IF($F25="⚠️ REORDER NOW",HYPERLINK("mailto:"&_xlfn.XLOOKUP($A25,'Item Master'!$A$4:$A$53,'Item Master'!$J$4:$J$53,"")&"?subject="&SUBSTITUTE("URGENT restock request - "&$B25&" ("&$A25&")"," ","%20")&"&body="&SUBSTITUTE(SUBSTITUTE("Hello "&_xlfn.XLOOKUP($A25,'Item Master'!$A$4:$A$53,'Item Master'!$H$4:$H$53,"Supplier")&"," & CHAR(10) & "We urgently need to restock "&$B25&" (SKU "&$A25&"). Our current stock is "&TEXT($E25,"0")&" units, which is below our reorder threshold." & CHAR(10) & "Please confirm availability, unit price and lead time by return." & CHAR(10) & "Kind regards," & CHAR(10) & "Momentum Mind Store"," ","%20"),CHAR(10),"%0D%0A"),"✉️ EMAIL"),"")) | I25: =IF($A25="","",$E25*_xlfn.XLOOKUP($A25,'Item Master'!$A$4:$A$53,'Item Master'!$D$4:$D$53,0))
A26: =IF(INDEX('Item Master'!$A$4:$A$53,18)="","",INDEX('Item Master'!$A$4:$A$53,18)) | B26: =IF($A26="","",_xlfn.XLOOKUP($A26,'Item Master'!$A$4:$A$53,'Item Master'!$B$4:$B$53,"")) | C26: =IF($A26="","",SUMIFS('Log Transaction'!$E$4:$E$303,'Log Transaction'!$C$4:$C$303,$A26,'Log Transaction'!$D$4:$D$303,"IN")) | D26: =IF($A26="","",SUMIFS('Log Transaction'!$E$4:$E$303,'Log Transaction'!$C$4:$C$303,$A26,'Log Transaction'!$D$4:$D$303,"OUT")+SUMIFS('Log Transaction'!$E$4:$E$303,'Log Transaction'!$C$4:$C$303,$A26,'Log Transaction'!$D$4:$D$303,"SHRINKAGE")) | E26: =IF($A26="","",$C26-$D26) | F26: =IF($A26="","",IF($E26<=_xlfn.XLOOKUP($A26,'Item Master'!$A$4:$A$53,'Item Master'!$F$4:$F$53,0)*0.1,"⚠️ REORDER NOW","✅ IN STOCK")) | G26: =IF($A26="","",IF($F26="⚠️ REORDER NOW",HYPERLINK("https://wa.me/"&SUBSTITUTE(SUBSTITUTE(SUBSTITUTE(SUBSTITUTE(SUBSTITUTE(SUBSTITUTE(_xlfn.XLOOKUP($A26,'Item Master'!$A$4:$A$53,'Item Master'!$I$4:$I$53,""),"+",""),"-","")," ",""),"(",""),")",""),".","")&"?text="&SUBSTITUTE("Hello "&_xlfn.XLOOKUP($A26,'Item Master'!$A$4:$A$53,'Item Master'!$H$4:$H$53,"Supplier")&", we urgently need more "&$B26&". Current stock is only "&TEXT($E26,"0")&" units. Please confirm availability and your fastest lead time. Thank you - Momentum Mind Store."," ","%20"),"💬 ORDER NOW"),"")) | H26: =IF($A26="","",IF($F26="⚠️ REORDER NOW",HYPERLINK("mailto:"&_xlfn.XLOOKUP($A26,'Item Master'!$A$4:$A$53,'Item Master'!$J$4:$J$53,"")&"?subject="&SUBSTITUTE("URGENT restock request - "&$B26&" ("&$A26&")"," ","%20")&"&body="&SUBSTITUTE(SUBSTITUTE("Hello "&_xlfn.XLOOKUP($A26,'Item Master'!$A$4:$A$53,'Item Master'!$H$4:$H$53,"Supplier")&"," & CHAR(10) & "We urgently need to restock "&$B26&" (SKU "&$A26&"). Our current stock is "&TEXT($E26,"0")&" units, which is below our reorder threshold." & CHAR(10) & "Please confirm availability, unit price and lead time by return." & CHAR(10) & "Kind regards," & CHAR(10) & "Momentum Mind Store"," ","%20"),CHAR(10),"%0D%0A"),"✉️ EMAIL"),"")) | I26: =IF($A26="","",$E26*_xlfn.XLOOKUP($A26,'Item Master'!$A$4:$A$53,'Item Master'!$D$4:$D$53,0))
A27: =IF(INDEX('Item Master'!$A$4:$A$53,19)="","",INDEX('Item Master'!$A$4:$A$53,19)) | B27: =IF($A27="","",_xlfn.XLOOKUP($A27,'Item Master'!$A$4:$A$53,'Item Master'!$B$4:$B$53,"")) | C27: =IF($A27="","",SUMIFS('Log Transaction'!$E$4:$E$303,'Log Transaction'!$C$4:$C$303,$A27,'Log Transaction'!$D$4:$D$303,"IN")) | D27: =IF($A27="","",SUMIFS('Log Transaction'!$E$4:$E$303,'Log Transaction'!$C$4:$C$303,$A27,'Log Transaction'!$D$4:$D$303,"OUT")+SUMIFS('Log Transaction'!$E$4:$E$303,'Log Transaction'!$C$4:$C$303,$A27,'Log Transaction'!$D$4:$D$303,"SHRINKAGE")) | E27: =IF($A27="","",$C27-$D27) | F27: =IF($A27="","",IF($E27<=_xlfn.XLOOKUP($A27,'Item Master'!$A$4:$A$53,'Item Master'!$F$4:$F$53,0)*0.1,"⚠️ REORDER NOW","✅ IN STOCK")) | G27: =IF($A27="","",IF($F27="⚠️ REORDER NOW",HYPERLINK("https://wa.me/"&SUBSTITUTE(SUBSTITUTE(SUBSTITUTE(SUBSTITUTE(SUBSTITUTE(SUBSTITUTE(_xlfn.XLOOKUP($A27,'Item Master'!$A$4:$A$53,'Item Master'!$I$4:$I$53,""),"+",""),"-","")," ",""),"(",""),")",""),".","")&"?text="&SUBSTITUTE("Hello "&_xlfn.XLOOKUP($A27,'Item Master'!$A$4:$A$53,'Item Master'!$H$4:$H$53,"Supplier")&", we urgently need more "&$B27&". Current stock is only "&TEXT($E27,"0")&" units. Please confirm availability and your fastest lead time. Thank you - Momentum Mind Store."," ","%20"),"💬 ORDER NOW"),"")) | H27: =IF($A27="","",IF($F27="⚠️ REORDER NOW",HYPERLINK("mailto:"&_xlfn.XLOOKUP($A27,'Item Master'!$A$4:$A$53,'Item Master'!$J$4:$J$53,"")&"?subject="&SUBSTITUTE("URGENT restock request - "&$B27&" ("&$A27&")"," ","%20")&"&body="&SUBSTITUTE(SUBSTITUTE("Hello "&_xlfn.XLOOKUP($A27,'Item Master'!$A$4:$A$53,'Item Master'!$H$4:$H$53,"Supplier")&"," & CHAR(10) & "We urgently need to restock "&$B27&" (SKU "&$A27&"). Our current stock is "&TEXT($E27,"0")&" units, which is below our reorder threshold." & CHAR(10) & "Please confirm availability, unit price and lead time by return." & CHAR(10) & "Kind regards," & CHAR(10) & "Momentum Mind Store"," ","%20"),CHAR(10),"%0D%0A"),"✉️ EMAIL"),"")) | I27: =IF($A27="","",$E27*_xlfn.XLOOKUP($A27,'Item Master'!$A$4:$A$53,'Item Master'!$D$4:$D$53,0))
A28: =IF(INDEX('Item Master'!$A$4:$A$53,20)="","",INDEX('Item Master'!$A$4:$A$53,20)) | B28: =IF($A28="","",_xlfn.XLOOKUP($A28,'Item Master'!$A$4:$A$53,'Item Master'!$B$4:$B$53,"")) | C28: =IF($A28="","",SUMIFS('Log Transaction'!$E$4:$E$303,'Log Transaction'!$C$4:$C$303,$A28,'Log Transaction'!$D$4:$D$303,"IN")) | D28: =IF($A28="","",SUMIFS('Log Transaction'!$E$4:$E$303,'Log Transaction'!$C$4:$C$303,$A28,'Log Transaction'!$D$4:$D$303,"OUT")+SUMIFS('Log Transaction'!$E$4:$E$303,'Log Transaction'!$C$4:$C$303,$A28,'Log Transaction'!$D$4:$D$303,"SHRINKAGE")) | E28: =IF($A28="","",$C28-$D28) | F28: =IF($A28="","",IF($E28<=_xlfn.XLOOKUP($A28,'Item Master'!$A$4:$A$53,'Item Master'!$F$4:$F$53,0)*0.1,"⚠️ REORDER NOW","✅ IN STOCK")) | G28: =IF($A28="","",IF($F28="⚠️ REORDER NOW",HYPERLINK("https://wa.me/"&SUBSTITUTE(SUBSTITUTE(SUBSTITUTE(SUBSTITUTE(SUBSTITUTE(SUBSTITUTE(_xlfn.XLOOKUP($A28,'Item Master'!$A$4:$A$53,'Item Master'!$I$4:$I$53,""),"+",""),"-","")," ",""),"(",""),")",""),".","")&"?text="&SUBSTITUTE("Hello "&_xlfn.XLOOKUP($A28,'Item Master'!$A$4:$A$53,'Item Master'!$H$4:$H$53,"Supplier")&", we urgently need more "&$B28&". Current stock is only "&TEXT($E28,"0")&" units. Please confirm availability and your fastest lead time. Thank you - Momentum Mind Store."," ","%20"),"💬 ORDER NOW"),"")) | H28: =IF($A28="","",IF($F28="⚠️ REORDER NOW",HYPERLINK("mailto:"&_xlfn.XLOOKUP($A28,'Item Master'!$A$4:$A$53,'Item Master'!$J$4:$J$53,"")&"?subject="&SUBSTITUTE("URGENT restock request - "&$B28&" ("&$A28&")"," ","%20")&"&body="&SUBSTITUTE(SUBSTITUTE("Hello "&_xlfn.XLOOKUP($A28,'Item Master'!$A$4:$A$53,'Item Master'!$H$4:$H$53,"Supplier")&"," & CHAR(10) & "We urgently need to restock "&$B28&" (SKU "&$A28&"). Our current stock is "&TEXT($E28,"0")&" units, which is below our reorder threshold." & CHAR(10) & "Please confirm availability, unit price and lead time by return." & CHAR(10) & "Kind regards," & CHAR(10) & "Momentum Mind Store"," ","%20"),CHAR(10),"%0D%0A"),"✉️ EMAIL"),"")) | I28: =IF($A28="","",$E28*_xlfn.XLOOKUP($A28,'Item Master'!$A$4:$A$53,'Item Master'!$D$4:$D$53,0))
A29: =IF(INDEX('Item Master'!$A$4:$A$53,21)="","",INDEX('Item Master'!$A$4:$A$53,21)) | B29: =IF($A29="","",_xlfn.XLOOKUP($A29,'Item Master'!$A$4:$A$53,'Item Master'!$B$4:$B$53,"")) | C29: =IF($A29="","",SUMIFS('Log Transaction'!$E$4:$E$303,'Log Transaction'!$C$4:$C$303,$A29,'Log Transaction'!$D$4:$D$303,"IN")) | D29: =IF($A29="","",SUMIFS('Log Transaction'!$E$4:$E$303,'Log Transaction'!$C$4:$C$303,$A29,'Log Transaction'!$D$4:$D$303,"OUT")+SUMIFS('Log Transaction'!$E$4:$E$303,'Log Transaction'!$C$4:$C$303,$A29,'Log Transaction'!$D$4:$D$303,"SHRINKAGE")) | E29: =IF($A29="","",$C29-$D29) | F29: =IF($A29="","",IF($E29<=_xlfn.XLOOKUP($A29,'Item Master'!$A$4:$A$53,'Item Master'!$F$4:$F$53,0)*0.1,"⚠️ REORDER NOW","✅ IN STOCK")) | G29: =IF($A29="","",IF($F29="⚠️ REORDER NOW",HYPERLINK("https://wa.me/"&SUBSTITUTE(SUBSTITUTE(SUBSTITUTE(SUBSTITUTE(SUBSTITUTE(SUBSTITUTE(_xlfn.XLOOKUP($A29,'Item Master'!$A$4:$A$53,'Item Master'!$I$4:$I$53,""),"+",""),"-","")," ",""),"(",""),")",""),".","")&"?text="&SUBSTITUTE("Hello "&_xlfn.XLOOKUP($A29,'Item Master'!$A$4:$A$53,'Item Master'!$H$4:$H$53,"Supplier")&", we urgently need more "&$B29&". Current stock is only "&TEXT($E29,"0")&" units. Please confirm availability and your fastest lead time. Thank you - Momentum Mind Store."," ","%20"),"💬 ORDER NOW"),"")) | H29: =IF($A29="","",IF($F29="⚠️ REORDER NOW",HYPERLINK("mailto:"&_xlfn.XLOOKUP($A29,'Item Master'!$A$4:$A$53,'Item Master'!$J$4:$J$53,"")&"?subject="&SUBSTITUTE("URGENT restock request - "&$B29&" ("&$A29&")"," ","%20")&"&body="&SUBSTITUTE(SUBSTITUTE("Hello "&_xlfn.XLOOKUP($A29,'Item Master'!$A$4:$A$53,'Item Master'!$H$4:$H$53,"Supplier")&"," & CHAR(10) & "We urgently need to restock "&$B29&" (SKU "&$A29&"). Our current stock is "&TEXT($E29,"0")&" units, which is below our reorder threshold." & CHAR(10) & "Please confirm availability, unit price and lead time by return." & CHAR(10) & "Kind regards," & CHAR(10) & "Momentum Mind Store"," ","%20"),CHAR(10),"%0D%0A"),"✉️ EMAIL"),"")) | I29: =IF($A29="","",$E29*_xlfn.XLOOKUP($A29,'Item Master'!$A$4:$A$53,'Item Master'!$D$4:$D$53,0))
A30: =IF(INDEX('Item Master'!$A$4:$A$53,22)="","",INDEX('Item Master'!$A$4:$A$53,22)) | B30: =IF($A30="","",_xlfn.XLOOKUP($A30,'Item Master'!$A$4:$A$53,'Item Master'!$B$4:$B$53,"")) | C30: =IF($A30="","",SUMIFS('Log Transaction'!$E$4:$E$303,'Log Transaction'!$C$4:$C$303,$A30,'Log Transaction'!$D$4:$D$303,"IN")) | D30: =IF($A30="","",SUMIFS('Log Transaction'!$E$4:$E$303,'Log Transaction'!$C$4:$C$303,$A30,'Log Transaction'!$D$4:$D$303,"OUT")+SUMIFS('Log Transaction'!$E$4:$E$303,'Log Transaction'!$C$4:$C$303,$A30,'Log Transaction'!$D$4:$D$303,"SHRINKAGE")) | E30: =IF($A30="","",$C30-$D30) | F30: =IF($A30="","",IF($E30<=_xlfn.XLOOKUP($A30,'Item Master'!$A$4:$A$53,'Item Master'!$F$4:$F$53,0)*0.1,"⚠️ REORDER NOW","✅ IN STOCK")) | G30: =IF($A30="","",IF($F30="⚠️ REORDER NOW",HYPERLINK("https://wa.me/"&SUBSTITUTE(SUBSTITUTE(SUBSTITUTE(SUBSTITUTE(SUBSTITUTE(SUBSTITUTE(_xlfn.XLOOKUP($A30,'Item Master'!$A$4:$A$53,'Item Master'!$I$4:$I$53,""),"+",""),"-","")," ",""),"(",""),")",""),".","")&"?text="&SUBSTITUTE("Hello "&_xlfn.XLOOKUP($A30,'Item Master'!$A$4:$A$53,'Item Master'!$H$4:$H$53,"Supplier")&", we urgently need more "&$B30&". Current stock is only "&TEXT($E30,"0")&" units. Please confirm availability and your fastest lead time. Thank you - Momentum Mind Store."," ","%20"),"💬 ORDER NOW"),"")) | H30: =IF($A30="","",IF($F30="⚠️ REORDER NOW",HYPERLINK("mailto:"&_xlfn.XLOOKUP($A30,'Item Master'!$A$4:$A$53,'Item Master'!$J$4:$J$53,"")&"?subject="&SUBSTITUTE("URGENT restock request - "&$B30&" ("&$A30&")"," ","%20")&"&body="&SUBSTITUTE(SUBSTITUTE("Hello "&_xlfn.XLOOKUP($A30,'Item Master'!$A$4:$A$53,'Item Master'!$H$4:$H$53,"Supplier")&"," & CHAR(10) & "We urgently need to restock "&$B30&" (SKU "&$A30&"). Our current stock is "&TEXT($E30,"0")&" units, which is below our reorder threshold." & CHAR(10) & "Please confirm availability, unit price and lead time by return." & CHAR(10) & "Kind regards," & CHAR(10) & "Momentum Mind Store"," ","%20"),CHAR(10),"%0D%0A"),"✉️ EMAIL"),"")) | I30: =IF($A30="","",$E30*_xlfn.XLOOKUP($A30,'Item Master'!$A$4:$A$53,'Item Master'!$D$4:$D$53,0))
A31: =IF(INDEX('Item Master'!$A$4:$A$53,23)="","",INDEX('Item Master'!$A$4:$A$53,23)) | B31: =IF($A31="","",_xlfn.XLOOKUP($A31,'Item Master'!$A$4:$A$53,'Item Master'!$B$4:$B$53,"")) | C31: =IF($A31="","",SUMIFS('Log Transaction'!$E$4:$E$303,'Log Transaction'!$C$4:$C$303,$A31,'Log Transaction'!$D$4:$D$303,"IN")) | D31: =IF($A31="","",SUMIFS('Log Transaction'!$E$4:$E$303,'Log Transaction'!$C$4:$C$303,$A31,'Log Transaction'!$D$4:$D$303,"OUT")+SUMIFS('Log Transaction'!$E$4:$E$303,'Log Transaction'!$C$4:$C$303,$A31,'Log Transaction'!$D$4:$D$303,"SHRINKAGE")) | E31: =IF($A31="","",$C31-$D31) | F31: =IF($A31="","",IF($E31<=_xlfn.XLOOKUP($A31,'Item Master'!$A$4:$A$53,'Item Master'!$F$4:$F$53,0)*0.1,"⚠️ REORDER NOW","✅ IN STOCK")) | G31: =IF($A31="","",IF($F31="⚠️ REORDER NOW",HYPERLINK("https://wa.me/"&SUBSTITUTE(SUBSTITUTE(SUBSTITUTE(SUBSTITUTE(SUBSTITUTE(SUBSTITUTE(_xlfn.XLOOKUP($A31,'Item Master'!$A$4:$A$53,'Item Master'!$I$4:$I$53,""),"+",""),"-","")," ",""),"(",""),")",""),".","")&"?text="&SUBSTITUTE("Hello "&_xlfn.XLOOKUP($A31,'Item Master'!$A$4:$A$53,'Item Master'!$H$4:$H$53,"Supplier")&", we urgently need more "&$B31&". Current stock is only "&TEXT($E31,"0")&" units. Please confirm availability and your fastest lead time. Thank you - Momentum Mind Store."," ","%20"),"💬 ORDER NOW"),"")) | H31: =IF($A31="","",IF($F31="⚠️ REORDER NOW",HYPERLINK("mailto:"&_xlfn.XLOOKUP($A31,'Item Master'!$A$4:$A$53,'Item Master'!$J$4:$J$53,"")&"?subject="&SUBSTITUTE("URGENT restock request - "&$B31&" ("&$A31&")"," ","%20")&"&body="&SUBSTITUTE(SUBSTITUTE("Hello "&_xlfn.XLOOKUP($A31,'Item Master'!$A$4:$A$53,'Item Master'!$H$4:$H$53,"Supplier")&"," & CHAR(10) & "We urgently need to restock "&$B31&" (SKU "&$A31&"). Our current stock is "&TEXT($E31,"0")&" units, which is below our reorder threshold." & CHAR(10) & "Please confirm availability, unit price and lead time by return." & CHAR(10) & "Kind regards," & CHAR(10) & "Momentum Mind Store"," ","%20"),CHAR(10),"%0D%0A"),"✉️ EMAIL"),"")) | I31: =IF($A31="","",$E31*_xlfn.XLOOKUP($A31,'Item Master'!$A$4:$A$53,'Item Master'!$D$4:$D$53,0))
A32: =IF(INDEX('Item Master'!$A$4:$A$53,24)="","",INDEX('Item Master'!$A$4:$A$53,24)) | B32: =IF($A32="","",_xlfn.XLOOKUP($A32,'Item Master'!$A$4:$A$53,'Item Master'!$B$4:$B$53,"")) | C32: =IF($A32="","",SUMIFS('Log Transaction'!$E$4:$E$303,'Log Transaction'!$C$4:$C$303,$A32,'Log Transaction'!$D$4:$D$303,"IN")) | D32: =IF($A32="","",SUMIFS('Log Transaction'!$E$4:$E$303,'Log Transaction'!$C$4:$C$303,$A32,'Log Transaction'!$D$4:$D$303,"OUT")+SUMIFS('Log Transaction'!$E$4:$E$303,'Log Transaction'!$C$4:$C$303,$A32,'Log Transaction'!$D$4:$D$303,"SHRINKAGE")) | E32: =IF($A32="","",$C32-$D32) | F32: =IF($A32="","",IF($E32<=_xlfn.XLOOKUP($A32,'Item Master'!$A$4:$A$53,'Item Master'!$F$4:$F$53,0)*0.1,"⚠️ REORDER NOW","✅ IN STOCK")) | G32: =IF($A32="","",IF($F32="⚠️ REORDER NOW",HYPERLINK("https://wa.me/"&SUBSTITUTE(SUBSTITUTE(SUBSTITUTE(SUBSTITUTE(SUBSTITUTE(SUBSTITUTE(_xlfn.XLOOKUP($A32,'Item Master'!$A$4:$A$53,'Item Master'!$I$4:$I$53,""),"+",""),"-","")," ",""),"(",""),")",""),".","")&"?text="&SUBSTITUTE("Hello "&_xlfn.XLOOKUP($A32,'Item Master'!$A$4:$A$53,'Item Master'!$H$4:$H$53,"Supplier")&", we urgently need more "&$B32&". Current stock is only "&TEXT($E32,"0")&" units. Please confirm availability and your fastest lead time. Thank you - Momentum Mind Store."," ","%20"),"💬 ORDER NOW"),"")) | H32: =IF($A32="","",IF($F32="⚠️ REORDER NOW",HYPERLINK("mailto:"&_xlfn.XLOOKUP($A32,'Item Master'!$A$4:$A$53,'Item Master'!$J$4:$J$53,"")&"?subject="&SUBSTITUTE("URGENT restock request - "&$B32&" ("&$A32&")"," ","%20")&"&body="&SUBSTITUTE(SUBSTITUTE("Hello "&_xlfn.XLOOKUP($A32,'Item Master'!$A$4:$A$53,'Item Master'!$H$4:$H$53,"Supplier")&"," & CHAR(10) & "We urgently need to restock "&$B32&" (SKU "&$A32&"). Our current stock is "&TEXT($E32,"0")&" units, which is below our reorder threshold." & CHAR(10) & "Please confirm availability, unit price and lead time by return." & CHAR(10) & "Kind regards," & CHAR(10) & "Momentum Mind Store"," ","%20"),CHAR(10),"%0D%0A"),"✉️ EMAIL"),"")) | I32: =IF($A32="","",$E32*_xlfn.XLOOKUP($A32,'Item Master'!$A$4:$A$53,'Item Master'!$D$4:$D$53,0))
A33: =IF(INDEX('Item Master'!$A$4:$A$53,25)="","",INDEX('Item Master'!$A$4:$A$53,25)) | B33: =IF($A33="","",_xlfn.XLOOKUP($A33,'Item Master'!$A$4:$A$53,'Item Master'!$B$4:$B$53,"")) | C33: =IF($A33="","",SUMIFS('Log Transaction'!$E$4:$E$303,'Log Transaction'!$C$4:$C$303,$A33,'Log Transaction'!$D$4:$D$303,"IN")) | D33: =IF($A33="","",SUMIFS('Log Transaction'!$E$4:$E$303,'Log Transaction'!$C$4:$C$303,$A33,'Log Transaction'!$D$4:$D$303,"OUT")+SUMIFS('Log Transaction'!$E$4:$E$303,'Log Transaction'!$C$4:$C$303,$A33,'Log Transaction'!$D$4:$D$303,"SHRINKAGE")) | E33: =IF($A33="","",$C33-$D33) | F33: =IF($A33="","",IF($E33<=_xlfn.XLOOKUP($A33,'Item Master'!$A$4:$A$53,'Item Master'!$F$4:$F$53,0)*0.1,"⚠️ REORDER NOW","✅ IN STOCK")) | G33: =IF($A33="","",IF($F33="⚠️ REORDER NOW",HYPERLINK("https://wa.me/"&SUBSTITUTE(SUBSTITUTE(SUBSTITUTE(SUBSTITUTE(SUBSTITUTE(SUBSTITUTE(_xlfn.XLOOKUP($A33,'Item Master'!$A$4:$A$53,'Item Master'!$I$4:$I$53,""),"+",""),"-","")," ",""),"(",""),")",""),".","")&"?text="&SUBSTITUTE("Hello "&_xlfn.XLOOKUP($A33,'Item Master'!$A$4:$A$53,'Item Master'!$H$4:$H$53,"Supplier")&", we urgently need more "&$B33&". Current stock is only "&TEXT($E33,"0")&" units. Please confirm availability and your fastest lead time. Thank you - Momentum Mind Store."," ","%20"),"💬 ORDER NOW"),"")) | H33: =IF($A33="","",IF($F33="⚠️ REORDER NOW",HYPERLINK("mailto:"&_xlfn.XLOOKUP($A33,'Item Master'!$A$4:$A$53,'Item Master'!$J$4:$J$53,"")&"?subject="&SUBSTITUTE("URGENT restock request - "&$B33&" ("&$A33&")"," ","%20")&"&body="&SUBSTITUTE(SUBSTITUTE("Hello "&_xlfn.XLOOKUP($A33,'Item Master'!$A$4:$A$53,'Item Master'!$H$4:$H$53,"Supplier")&"," & CHAR(10) & "We urgently need to restock "&$B33&" (SKU "&$A33&"). Our current stock is "&TEXT($E33,"0")&" units, which is below our reorder threshold." & CHAR(10) & "Please confirm availability, unit price and lead time by return." & CHAR(10) & "Kind regards," & CHAR(10) & "Momentum Mind Store"," ","%20"),CHAR(10),"%0D%0A"),"✉️ EMAIL"),"")) | I33: =IF($A33="","",$E33*_xlfn.XLOOKUP($A33,'Item Master'!$A$4:$A$53,'Item Master'!$D$4:$D$53,0))
A34: =IF(INDEX('Item Master'!$A$4:$A$53,26)="","",INDEX('Item Master'!$A$4:$A$53,26)) | B34: =IF($A34="","",_xlfn.XLOOKUP($A34,'Item Master'!$A$4:$A$53,'Item Master'!$B$4:$B$53,"")) | C34: =IF($A34="","",SUMIFS('Log Transaction'!$E$4:$E$303,'Log Transaction'!$C$4:$C$303,$A34,'Log Transaction'!$D$4:$D$303,"IN")) | D34: =IF($A34="","",SUMIFS('Log Transaction'!$E$4:$E$303,'Log Transaction'!$C$4:$C$303,$A34,'Log Transaction'!$D$4:$D$303,"OUT")+SUMIFS('Log Transaction'!$E$4:$E$303,'Log Transaction'!$C$4:$C$303,$A34,'Log Transaction'!$D$4:$D$303,"SHRINKAGE")) | E34: =IF($A34="","",$C34-$D34) | F34: =IF($A34="","",IF($E34<=_xlfn.XLOOKUP($A34,'Item Master'!$A$4:$A$53,'Item Master'!$F$4:$F$53,0)*0.1,"⚠️ REORDER NOW","✅ IN STOCK")) | G34: =IF($A34="","",IF($F34="⚠️ REORDER NOW",HYPERLINK("https://wa.me/"&SUBSTITUTE(SUBSTITUTE(SUBSTITUTE(SUBSTITUTE(SUBSTITUTE(SUBSTITUTE(_xlfn.XLOOKUP($A34,'Item Master'!$A$4:$A$53,'Item Master'!$I$4:$I$53,""),"+",""),"-","")," ",""),"(",""),")",""),".","")&"?text="&SUBSTITUTE("Hello "&_xlfn.XLOOKUP($A34,'Item Master'!$A$4:$A$53,'Item Master'!$H$4:$H$53,"Supplier")&", we urgently need more "&$B34&". Current stock is only "&TEXT($E34,"0")&" units. Please confirm availability and your fastest lead time. Thank you - Momentum Mind Store."," ","%20"),"💬 ORDER NOW"),"")) | H34: =IF($A34="","",IF($F34="⚠️ REORDER NOW",HYPERLINK("mailto:"&_xlfn.XLOOKUP($A34,'Item Master'!$A$4:$A$53,'Item Master'!$J$4:$J$53,"")&"?subject="&SUBSTITUTE("URGENT restock request - "&$B34&" ("&$A34&")"," ","%20")&"&body="&SUBSTITUTE(SUBSTITUTE("Hello "&_xlfn.XLOOKUP($A34,'Item Master'!$A$4:$A$53,'Item Master'!$H$4:$H$53,"Supplier")&"," & CHAR(10) & "We urgently need to restock "&$B34&" (SKU "&$A34&"). Our current stock is "&TEXT($E34,"0")&" units, which is below our reorder threshold." & CHAR(10) & "Please confirm availability, unit price and lead time by return." & CHAR(10) & "Kind regards," & CHAR(10) & "Momentum Mind Store"," ","%20"),CHAR(10),"%0D%0A"),"✉️ EMAIL"),"")) | I34: =IF($A34="","",$E34*_xlfn.XLOOKUP($A34,'Item Master'!$A$4:$A$53,'Item Master'!$D$4:$D$53,0))
A35: =IF(INDEX('Item Master'!$A$4:$A$53,27)="","",INDEX('Item Master'!$A$4:$A$53,27)) | B35: =IF($A35="","",_xlfn.XLOOKUP($A35,'Item Master'!$A$4:$A$53,'Item Master'!$B$4:$B$53,"")) | C35: =IF($A35="","",SUMIFS('Log Transaction'!$E$4:$E$303,'Log Transaction'!$C$4:$C$303,$A35,'Log Transaction'!$D$4:$D$303,"IN")) | D35: =IF($A35="","",SUMIFS('Log Transaction'!$E$4:$E$303,'Log Transaction'!$C$4:$C$303,$A35,'Log Transaction'!$D$4:$D$303,"OUT")+SUMIFS('Log Transaction'!$E$4:$E$303,'Log Transaction'!$C$4:$C$303,$A35,'Log Transaction'!$D$4:$D$303,"SHRINKAGE")) | E35: =IF($A35="","",$C35-$D35) | F35: =IF($A35="","",IF($E35<=_xlfn.XLOOKUP($A35,'Item Master'!$A$4:$A$53,'Item Master'!$F$4:$F$53,0)*0.1,"⚠️ REORDER NOW","✅ IN STOCK")) | G35: =IF($A35="","",IF($F35="⚠️ REORDER NOW",HYPERLINK("https://wa.me/"&SUBSTITUTE(SUBSTITUTE(SUBSTITUTE(SUBSTITUTE(SUBSTITUTE(SUBSTITUTE(_xlfn.XLOOKUP($A35,'Item Master'!$A$4:$A$53,'Item Master'!$I$4:$I$53,""),"+",""),"-","")," ",""),"(",""),")",""),".","")&"?text="&SUBSTITUTE("Hello "&_xlfn.XLOOKUP($A35,'Item Master'!$A$4:$A$53,'Item Master'!$H$4:$H$53,"Supplier")&", we urgently need more "&$B35&". Current stock is only "&TEXT($E35,"0")&" units. Please confirm availability and your fastest lead time. Thank you - Momentum Mind Store."," ","%20"),"💬 ORDER NOW"),"")) | H35: =IF($A35="","",IF($F35="⚠️ REORDER NOW",HYPERLINK("mailto:"&_xlfn.XLOOKUP($A35,'Item Master'!$A$4:$A$53,'Item Master'!$J$4:$J$53,"")&"?subject="&SUBSTITUTE("URGENT restock request - "&$B35&" ("&$A35&")"," ","%20")&"&body="&SUBSTITUTE(SUBSTITUTE("Hello "&_xlfn.XLOOKUP($A35,'Item Master'!$A$4:$A$53,'Item Master'!$H$4:$H$53,"Supplier")&"," & CHAR(10) & "We urgently need to restock "&$B35&" (SKU "&$A35&"). Our current stock is "&TEXT($E35,"0")&" units, which is below our reorder threshold." & CHAR(10) & "Please confirm availability, unit price and lead time by return." & CHAR(10) & "Kind regards," & CHAR(10) & "Momentum Mind Store"," ","%20"),CHAR(10),"%0D%0A"),"✉️ EMAIL"),"")) | I35: =IF($A35="","",$E35*_xlfn.XLOOKUP($A35,'Item Master'!$A$4:$A$53,'Item Master'!$D$4:$D$53,0))
